<mujoco>
  <compiler autolimits="true"/>

  <default>
    <site type="sphere" rgba="1 0 0 1" size="0.005"/>
    <tendon rgba="0 1 0 1"/>
  </default>
  
  <visual>
    <headlight diffuse=".7 .7 .7"/>
  </visual>

  <worldbody>
    <body name="arm">
      <joint name="arm" axis="0 1 0" range="-120 120" damping=".04"/>
      <geom name="shoulder" type="cylinder" size=".05 .01" zaxis="0 1 0"/>
      <geom name="arm" type="box" size=".01" fromto="0 0 0 -.3 0 0"/>
      <geom name="crossbar" type="box" size=".01" fromto="-.1 0 -.05 -.1 0 .05"/>
      <site name="arm" pos="-.1 0 .05"/>
      <site name="arm_d" pos="-.1 0 -.05"/>
    </body>
    <site name="up" pos="0 0 .1"/>
    <site name="relay_u" pos=".1 0 .05"/>
    <body name="slider_u" pos=".2 0 .05">
      <joint name="slider_u" axis="-1 0 0" type="slide" damping=".1" range="-1. .1"/>
      <geom name="slider_u" type="box" size=".01 .01 .01"/>
      <site name="slider_u" pos="0 0 .01"/>
    </body>
    <site name="down" pos="0 0 -.1"/>
    <site name="relay_d" pos=".1 0 -.05"/>
    <body name="slider_d" pos=".2 0 -.05">
      <joint name="slider_d" axis="-1 0 0" type="slide" damping=".1" range="-1. .1"/>
      <geom name="slider_d" type="box" size=".01 .01 .01"/>
      <site name="slider_d" pos="0 0 .01"/>
    </body>
  </worldbody>

  <tendon>
    <spatial name="rope_u" range="0 .35">
      <site site="slider_u"/>
      <site site="relay_u"/>
      <geom geom="shoulder" sidesite="up"/>
      <site site="arm"/>
    </spatial>
    <spatial name="rope_d" range="0 .35">
      <site site="slider_d"/>
      <site site="relay_d"/>
      <geom geom="shoulder" sidesite="down"/>
      <site site="arm_d"/>
    </spatial>
  </tendon>

  <actuator>
    <!-- <position name="slider_u" joint="slider_u" ctrlrange="-.1 .1" kp="100"/> -->
    <motor name="slider_u" joint="slider_u" ctrlrange="-10. 0."/>
    <motor name="slider_d" joint="slider_d" ctrlrange="-10. 0."/>
  </actuator>

  <sensor>
    <tendonlimitfrc tendon="rope_u"/>
    <tendonlimitfrc tendon="rope_d"/>
  </sensor>
</mujoco>